[2025-01-07T12:11:12.775+0000] {local_task_job_runner.py:120} INFO - ::group::Pre task execution logs
[2025-01-07T12:11:12.804+0000] {taskinstance.py:2076} INFO - Dependencies all met for dep_context=non-requeueable deps ti=<TaskInstance: first_dag.random_dice scheduled__2025-01-06T00:00:00+00:00 [queued]>
[2025-01-07T12:11:12.816+0000] {taskinstance.py:2076} INFO - Dependencies all met for dep_context=requeueable deps ti=<TaskInstance: first_dag.random_dice scheduled__2025-01-06T00:00:00+00:00 [queued]>
[2025-01-07T12:11:12.817+0000] {taskinstance.py:2306} INFO - Starting attempt 2 of 3
[2025-01-07T12:11:12.834+0000] {taskinstance.py:2330} INFO - Executing <Task(PythonOperator): random_dice> on 2025-01-06 00:00:00+00:00
[2025-01-07T12:11:12.841+0000] {warnings.py:112} WARNING - /home/***/.local/lib/python3.12/site-packages/***/task/task_runner/standard_task_runner.py:61: DeprecationWarning: This process (pid=676) is multi-threaded, use of fork() may lead to deadlocks in the child.
  pid = os.fork()

[2025-01-07T12:11:12.843+0000] {standard_task_runner.py:63} INFO - Started process 677 to run task
[2025-01-07T12:11:12.843+0000] {standard_task_runner.py:90} INFO - Running: ['***', 'tasks', 'run', 'first_dag', 'random_dice', 'scheduled__2025-01-06T00:00:00+00:00', '--job-id', '26', '--raw', '--subdir', 'DAGS_FOLDER/skelet.py', '--cfg-path', '/tmp/tmpj7y3dkck']
[2025-01-07T12:11:12.844+0000] {standard_task_runner.py:91} INFO - Job 26: Subtask random_dice
[2025-01-07T12:11:12.904+0000] {task_command.py:426} INFO - Running <TaskInstance: first_dag.random_dice scheduled__2025-01-06T00:00:00+00:00 [running]> on host 006c1e931b5c
[2025-01-07T12:11:12.997+0000] {taskinstance.py:2648} INFO - Exporting env vars: AIRFLOW_CTX_DAG_OWNER='***' AIRFLOW_CTX_DAG_ID='first_dag' AIRFLOW_CTX_TASK_ID='random_dice' AIRFLOW_CTX_EXECUTION_DATE='2025-01-06T00:00:00+00:00' AIRFLOW_CTX_TRY_NUMBER='2' AIRFLOW_CTX_DAG_RUN_ID='scheduled__2025-01-06T00:00:00+00:00'
[2025-01-07T12:11:12.998+0000] {taskinstance.py:430} INFO - ::endgroup::
[2025-01-07T12:11:13.015+0000] {taskinstance.py:441} INFO - ::group::Post task execution logs
[2025-01-07T12:11:13.016+0000] {taskinstance.py:2905} ERROR - Task failed with exception
Traceback (most recent call last):
  File "/home/airflow/.local/lib/python3.12/site-packages/airflow/models/taskinstance.py", line 465, in _execute_task
    result = _execute_callable(context=context, **execute_callable_kwargs)
             ^^^^^^^^^^^^^^^^^^^^^^^^^^^^^^^^^^^^^^^^^^^^^^^^^^^^^^^^^^^^^
  File "/home/airflow/.local/lib/python3.12/site-packages/airflow/models/taskinstance.py", line 432, in _execute_callable
    return execute_callable(context=context, **execute_callable_kwargs)
           ^^^^^^^^^^^^^^^^^^^^^^^^^^^^^^^^^^^^^^^^^^^^^^^^^^^^^^^^^^^^
  File "/home/airflow/.local/lib/python3.12/site-packages/airflow/models/baseoperator.py", line 401, in wrapper
    return func(self, *args, **kwargs)
           ^^^^^^^^^^^^^^^^^^^^^^^^^^^
  File "/home/airflow/.local/lib/python3.12/site-packages/airflow/operators/python.py", line 235, in execute
    return_value = self.execute_callable()
                   ^^^^^^^^^^^^^^^^^^^^^^^
  File "/home/airflow/.local/lib/python3.12/site-packages/airflow/operators/python.py", line 252, in execute_callable
    return self.python_callable(*self.op_args, **self.op_kwargs)
           ^^^^^^^^^^^^^^^^^^^^^^^^^^^^^^^^^^^^^^^^^^^^^^^^^^^^^
  File "/opt/airflow/dags/skelet.py", line 17, in random_dice
    raise ValueError(f'Odd {val}')
ValueError: Odd 5
[2025-01-07T12:11:13.029+0000] {taskinstance.py:1206} INFO - Marking task as UP_FOR_RETRY. dag_id=first_dag, task_id=random_dice, run_id=scheduled__2025-01-06T00:00:00+00:00, execution_date=20250106T000000, start_date=20250107T121112, end_date=20250107T121113
[2025-01-07T12:11:13.044+0000] {standard_task_runner.py:110} ERROR - Failed to execute job 26 for task random_dice (Odd 5; 677)
[2025-01-07T12:11:13.057+0000] {local_task_job_runner.py:240} INFO - Task exited with return code 1
[2025-01-07T12:11:13.077+0000] {taskinstance.py:3503} INFO - 0 downstream tasks scheduled from follow-on schedule check
[2025-01-07T12:11:13.080+0000] {local_task_job_runner.py:222} INFO - ::endgroup::
[2025-01-07T13:02:38.392+0000] {local_task_job_runner.py:120} INFO - ::group::Pre task execution logs
[2025-01-07T13:02:38.424+0000] {taskinstance.py:2076} INFO - Dependencies all met for dep_context=non-requeueable deps ti=<TaskInstance: first_dag.random_dice scheduled__2025-01-06T00:00:00+00:00 [queued]>
[2025-01-07T13:02:38.437+0000] {taskinstance.py:2076} INFO - Dependencies all met for dep_context=requeueable deps ti=<TaskInstance: first_dag.random_dice scheduled__2025-01-06T00:00:00+00:00 [queued]>
[2025-01-07T13:02:38.438+0000] {taskinstance.py:2306} INFO - Starting attempt 2 of 3
[2025-01-07T13:02:38.458+0000] {taskinstance.py:2330} INFO - Executing <Task(PythonOperator): random_dice> on 2025-01-06 00:00:00+00:00
[2025-01-07T13:02:38.465+0000] {warnings.py:112} WARNING - /home/***/.local/lib/python3.12/site-packages/***/task/task_runner/standard_task_runner.py:61: DeprecationWarning: This process (pid=1384) is multi-threaded, use of fork() may lead to deadlocks in the child.
  pid = os.fork()

[2025-01-07T13:02:38.467+0000] {standard_task_runner.py:63} INFO - Started process 1386 to run task
[2025-01-07T13:02:38.467+0000] {standard_task_runner.py:90} INFO - Running: ['***', 'tasks', 'run', 'first_dag', 'random_dice', 'scheduled__2025-01-06T00:00:00+00:00', '--job-id', '54', '--raw', '--subdir', 'DAGS_FOLDER/skelet.py', '--cfg-path', '/tmp/tmpsj9pzyv0']
[2025-01-07T13:02:38.468+0000] {standard_task_runner.py:91} INFO - Job 54: Subtask random_dice
[2025-01-07T13:02:38.523+0000] {task_command.py:426} INFO - Running <TaskInstance: first_dag.random_dice scheduled__2025-01-06T00:00:00+00:00 [running]> on host 006c1e931b5c
[2025-01-07T13:02:38.640+0000] {taskinstance.py:2648} INFO - Exporting env vars: AIRFLOW_CTX_DAG_OWNER='***' AIRFLOW_CTX_DAG_ID='first_dag' AIRFLOW_CTX_TASK_ID='random_dice' AIRFLOW_CTX_EXECUTION_DATE='2025-01-06T00:00:00+00:00' AIRFLOW_CTX_TRY_NUMBER='2' AIRFLOW_CTX_DAG_RUN_ID='scheduled__2025-01-06T00:00:00+00:00'
[2025-01-07T13:02:38.642+0000] {taskinstance.py:430} INFO - ::endgroup::
[2025-01-07T13:02:38.658+0000] {python.py:237} INFO - Done. Returned value was: None
[2025-01-07T13:02:38.660+0000] {taskinstance.py:441} INFO - ::group::Post task execution logs
[2025-01-07T13:02:38.671+0000] {taskinstance.py:1206} INFO - Marking task as SUCCESS. dag_id=first_dag, task_id=random_dice, run_id=scheduled__2025-01-06T00:00:00+00:00, execution_date=20250106T000000, start_date=20250107T130238, end_date=20250107T130238
[2025-01-07T13:02:38.722+0000] {local_task_job_runner.py:240} INFO - Task exited with return code 0
[2025-01-07T13:02:38.740+0000] {taskinstance.py:3503} INFO - 0 downstream tasks scheduled from follow-on schedule check
[2025-01-07T13:02:38.743+0000] {local_task_job_runner.py:222} INFO - ::endgroup::
