[2025-01-07T12:11:00.969+0000] {local_task_job_runner.py:120} INFO - ::group::Pre task execution logs
[2025-01-07T12:11:01.023+0000] {taskinstance.py:2076} INFO - Dependencies all met for dep_context=non-requeueable deps ti=<TaskInstance: first_dag.random_dice scheduled__2025-01-06T00:00:00+00:00 [queued]>
[2025-01-07T12:11:01.038+0000] {taskinstance.py:2076} INFO - Dependencies all met for dep_context=requeueable deps ti=<TaskInstance: first_dag.random_dice scheduled__2025-01-06T00:00:00+00:00 [queued]>
[2025-01-07T12:11:01.039+0000] {taskinstance.py:2306} INFO - Starting attempt 1 of 3
[2025-01-07T12:11:01.059+0000] {taskinstance.py:2330} INFO - Executing <Task(PythonOperator): random_dice> on 2025-01-06 00:00:00+00:00
[2025-01-07T12:11:01.069+0000] {standard_task_runner.py:90} INFO - Running: ['***', 'tasks', 'run', 'first_dag', 'random_dice', 'scheduled__2025-01-06T00:00:00+00:00', '--job-id', '24', '--raw', '--subdir', 'DAGS_FOLDER/skelet.py', '--cfg-path', '/tmp/tmpd7idz6c2']
[2025-01-07T12:11:01.068+0000] {warnings.py:112} WARNING - /home/***/.local/lib/python3.12/site-packages/***/task/task_runner/standard_task_runner.py:61: DeprecationWarning: This process (pid=672) is multi-threaded, use of fork() may lead to deadlocks in the child.
  pid = os.fork()

[2025-01-07T12:11:01.070+0000] {standard_task_runner.py:91} INFO - Job 24: Subtask random_dice
[2025-01-07T12:11:01.070+0000] {standard_task_runner.py:63} INFO - Started process 673 to run task
[2025-01-07T12:11:01.133+0000] {task_command.py:426} INFO - Running <TaskInstance: first_dag.random_dice scheduled__2025-01-06T00:00:00+00:00 [running]> on host 006c1e931b5c
[2025-01-07T12:11:01.247+0000] {taskinstance.py:2648} INFO - Exporting env vars: AIRFLOW_CTX_DAG_OWNER='***' AIRFLOW_CTX_DAG_ID='first_dag' AIRFLOW_CTX_TASK_ID='random_dice' AIRFLOW_CTX_EXECUTION_DATE='2025-01-06T00:00:00+00:00' AIRFLOW_CTX_TRY_NUMBER='1' AIRFLOW_CTX_DAG_RUN_ID='scheduled__2025-01-06T00:00:00+00:00'
[2025-01-07T12:11:01.249+0000] {taskinstance.py:430} INFO - ::endgroup::
[2025-01-07T12:11:01.307+0000] {taskinstance.py:441} INFO - ::group::Post task execution logs
[2025-01-07T12:11:01.308+0000] {taskinstance.py:2905} ERROR - Task failed with exception
Traceback (most recent call last):
  File "/home/airflow/.local/lib/python3.12/site-packages/airflow/models/taskinstance.py", line 465, in _execute_task
    result = _execute_callable(context=context, **execute_callable_kwargs)
             ^^^^^^^^^^^^^^^^^^^^^^^^^^^^^^^^^^^^^^^^^^^^^^^^^^^^^^^^^^^^^
  File "/home/airflow/.local/lib/python3.12/site-packages/airflow/models/taskinstance.py", line 432, in _execute_callable
    return execute_callable(context=context, **execute_callable_kwargs)
           ^^^^^^^^^^^^^^^^^^^^^^^^^^^^^^^^^^^^^^^^^^^^^^^^^^^^^^^^^^^^
  File "/home/airflow/.local/lib/python3.12/site-packages/airflow/models/baseoperator.py", line 401, in wrapper
    return func(self, *args, **kwargs)
           ^^^^^^^^^^^^^^^^^^^^^^^^^^^
  File "/home/airflow/.local/lib/python3.12/site-packages/airflow/operators/python.py", line 235, in execute
    return_value = self.execute_callable()
                   ^^^^^^^^^^^^^^^^^^^^^^^
  File "/home/airflow/.local/lib/python3.12/site-packages/airflow/operators/python.py", line 252, in execute_callable
    return self.python_callable(*self.op_args, **self.op_kwargs)
           ^^^^^^^^^^^^^^^^^^^^^^^^^^^^^^^^^^^^^^^^^^^^^^^^^^^^^
  File "/opt/airflow/dags/skelet.py", line 17, in random_dice
    raise ValueError(f'Odd {val}')
ValueError: Odd 3
[2025-01-07T12:11:01.326+0000] {taskinstance.py:1206} INFO - Marking task as UP_FOR_RETRY. dag_id=first_dag, task_id=random_dice, run_id=scheduled__2025-01-06T00:00:00+00:00, execution_date=20250106T000000, start_date=20250107T121101, end_date=20250107T121101
[2025-01-07T12:11:01.345+0000] {standard_task_runner.py:110} ERROR - Failed to execute job 24 for task random_dice (Odd 3; 673)
[2025-01-07T12:11:01.369+0000] {local_task_job_runner.py:240} INFO - Task exited with return code 1
[2025-01-07T12:11:01.391+0000] {taskinstance.py:3503} INFO - 0 downstream tasks scheduled from follow-on schedule check
[2025-01-07T12:11:01.394+0000] {local_task_job_runner.py:222} INFO - ::endgroup::
[2025-01-07T13:02:27.000+0000] {local_task_job_runner.py:120} INFO - ::group::Pre task execution logs
[2025-01-07T13:02:27.031+0000] {taskinstance.py:2076} INFO - Dependencies all met for dep_context=non-requeueable deps ti=<TaskInstance: first_dag.random_dice scheduled__2025-01-06T00:00:00+00:00 [queued]>
[2025-01-07T13:02:27.044+0000] {taskinstance.py:2076} INFO - Dependencies all met for dep_context=requeueable deps ti=<TaskInstance: first_dag.random_dice scheduled__2025-01-06T00:00:00+00:00 [queued]>
[2025-01-07T13:02:27.045+0000] {taskinstance.py:2306} INFO - Starting attempt 1 of 3
[2025-01-07T13:02:27.067+0000] {taskinstance.py:2330} INFO - Executing <Task(PythonOperator): random_dice> on 2025-01-06 00:00:00+00:00
[2025-01-07T13:02:27.074+0000] {warnings.py:112} WARNING - /home/***/.local/lib/python3.12/site-packages/***/task/task_runner/standard_task_runner.py:61: DeprecationWarning: This process (pid=1373) is multi-threaded, use of fork() may lead to deadlocks in the child.
  pid = os.fork()

[2025-01-07T13:02:27.076+0000] {standard_task_runner.py:63} INFO - Started process 1375 to run task
[2025-01-07T13:02:27.076+0000] {standard_task_runner.py:90} INFO - Running: ['***', 'tasks', 'run', 'first_dag', 'random_dice', 'scheduled__2025-01-06T00:00:00+00:00', '--job-id', '49', '--raw', '--subdir', 'DAGS_FOLDER/skelet.py', '--cfg-path', '/tmp/tmp0nu6m6y_']
[2025-01-07T13:02:27.077+0000] {standard_task_runner.py:91} INFO - Job 49: Subtask random_dice
[2025-01-07T13:02:27.139+0000] {task_command.py:426} INFO - Running <TaskInstance: first_dag.random_dice scheduled__2025-01-06T00:00:00+00:00 [running]> on host 006c1e931b5c
[2025-01-07T13:02:27.282+0000] {taskinstance.py:2648} INFO - Exporting env vars: AIRFLOW_CTX_DAG_OWNER='***' AIRFLOW_CTX_DAG_ID='first_dag' AIRFLOW_CTX_TASK_ID='random_dice' AIRFLOW_CTX_EXECUTION_DATE='2025-01-06T00:00:00+00:00' AIRFLOW_CTX_TRY_NUMBER='1' AIRFLOW_CTX_DAG_RUN_ID='scheduled__2025-01-06T00:00:00+00:00'
[2025-01-07T13:02:27.283+0000] {taskinstance.py:430} INFO - ::endgroup::
[2025-01-07T13:02:27.300+0000] {taskinstance.py:441} INFO - ::group::Post task execution logs
[2025-01-07T13:02:27.301+0000] {taskinstance.py:2905} ERROR - Task failed with exception
Traceback (most recent call last):
  File "/home/airflow/.local/lib/python3.12/site-packages/airflow/models/taskinstance.py", line 465, in _execute_task
    result = _execute_callable(context=context, **execute_callable_kwargs)
             ^^^^^^^^^^^^^^^^^^^^^^^^^^^^^^^^^^^^^^^^^^^^^^^^^^^^^^^^^^^^^
  File "/home/airflow/.local/lib/python3.12/site-packages/airflow/models/taskinstance.py", line 432, in _execute_callable
    return execute_callable(context=context, **execute_callable_kwargs)
           ^^^^^^^^^^^^^^^^^^^^^^^^^^^^^^^^^^^^^^^^^^^^^^^^^^^^^^^^^^^^
  File "/home/airflow/.local/lib/python3.12/site-packages/airflow/models/baseoperator.py", line 401, in wrapper
    return func(self, *args, **kwargs)
           ^^^^^^^^^^^^^^^^^^^^^^^^^^^
  File "/home/airflow/.local/lib/python3.12/site-packages/airflow/operators/python.py", line 235, in execute
    return_value = self.execute_callable()
                   ^^^^^^^^^^^^^^^^^^^^^^^
  File "/home/airflow/.local/lib/python3.12/site-packages/airflow/operators/python.py", line 252, in execute_callable
    return self.python_callable(*self.op_args, **self.op_kwargs)
           ^^^^^^^^^^^^^^^^^^^^^^^^^^^^^^^^^^^^^^^^^^^^^^^^^^^^^
  File "/opt/airflow/dags/skelet.py", line 17, in random_dice
    raise ValueError(f'Odd {val}')
ValueError: Odd 1
[2025-01-07T13:02:27.317+0000] {taskinstance.py:1206} INFO - Marking task as UP_FOR_RETRY. dag_id=first_dag, task_id=random_dice, run_id=scheduled__2025-01-06T00:00:00+00:00, execution_date=20250106T000000, start_date=20250107T130227, end_date=20250107T130227
[2025-01-07T13:02:27.337+0000] {standard_task_runner.py:110} ERROR - Failed to execute job 49 for task random_dice (Odd 1; 1375)
[2025-01-07T13:02:27.371+0000] {local_task_job_runner.py:240} INFO - Task exited with return code 1
[2025-01-07T13:02:27.393+0000] {taskinstance.py:3503} INFO - 0 downstream tasks scheduled from follow-on schedule check
[2025-01-07T13:02:27.397+0000] {local_task_job_runner.py:222} INFO - ::endgroup::
